{"uuid": "8d3b8c21-ca81-4825-a7f6-7406d772270c", "children": ["6bf0852e-bb07-4e82-8c72-8e1c59fbc6a0"], "befores": [{"name": "setup", "status": "passed", "start": 1729068475954, "stop": 1729068476332}], "afters": [{"name": "setup::0", "status": "broken", "statusDetails": {"message": "urllib3.exceptions.MaxRetryError: HTTPConnectionPool(host='localhost', port=49015): Max retries exceeded with url: /session/39ae1d649a9022ff14781a72d2e1af6c/window (Caused by NewConnectionError('<urllib3.connection.HTTPConnection object at 0x762e41481790>: Failed to establish a new connection: [Errno 111] Connection refused'))\n", "trace": "  File \"/home/nsl42/anaconda3/lib/python3.9/site-packages/allure_commons/_allure.py\", line 221, in __call__\n    return self._fixture_function(*args, **kwargs)\n  File \"/home/nsl42/anaconda3/lib/python3.9/site-packages/_pytest/fixtures.py\", line 926, in _teardown_yield_fixture\n    next(it)\n  File \"/home/nsl42/Desktop/Automation/PhpTravels/TestCases/conftest.py\", line 34, in setup\n    driver.close()\n  File \"/home/nsl42/anaconda3/lib/python3.9/site-packages/selenium/webdriver/remote/webdriver.py\", line 458, in close\n    self.execute(Command.CLOSE)\n  File \"/home/nsl42/anaconda3/lib/python3.9/site-packages/selenium/webdriver/remote/webdriver.py\", line 345, in execute\n    response = self.command_executor.execute(driver_command, params)\n  File \"/home/nsl42/anaconda3/lib/python3.9/site-packages/selenium/webdriver/remote/remote_connection.py\", line 302, in execute\n    return self._request(command_info[0], url, body=data)\n  File \"/home/nsl42/anaconda3/lib/python3.9/site-packages/selenium/webdriver/remote/remote_connection.py\", line 322, in _request\n    response = self._conn.request(method, url, body=body, headers=headers)\n  File \"/home/nsl42/anaconda3/lib/python3.9/site-packages/urllib3/request.py\", line 74, in request\n    return self.request_encode_url(\n  File \"/home/nsl42/anaconda3/lib/python3.9/site-packages/urllib3/request.py\", line 96, in request_encode_url\n    return self.urlopen(method, url, **extra_kw)\n  File \"/home/nsl42/anaconda3/lib/python3.9/site-packages/urllib3/poolmanager.py\", line 376, in urlopen\n    response = conn.urlopen(method, u.request_uri, **kw)\n  File \"/home/nsl42/anaconda3/lib/python3.9/site-packages/urllib3/connectionpool.py\", line 815, in urlopen\n    return self.urlopen(\n  File \"/home/nsl42/anaconda3/lib/python3.9/site-packages/urllib3/connectionpool.py\", line 815, in urlopen\n    return self.urlopen(\n  File \"/home/nsl42/anaconda3/lib/python3.9/site-packages/urllib3/connectionpool.py\", line 815, in urlopen\n    return self.urlopen(\n  File \"/home/nsl42/anaconda3/lib/python3.9/site-packages/urllib3/connectionpool.py\", line 787, in urlopen\n    retries = retries.increment(\n  File \"/home/nsl42/anaconda3/lib/python3.9/site-packages/urllib3/util/retry.py\", line 592, in increment\n    raise MaxRetryError(_pool, url, error or ResponseError(cause))\n"}, "start": 1729068495478, "stop": 1729068495480}], "start": 1729068475954, "stop": 1729068495480}